[MFLOG|0|2023-11-22T16:25:51.221710Z|runtime|70a2fbae-4ecd-4fd8-baf6-00315e5331fd]<flow P2 step start> failed:
[MFLOG|0|2023-11-22T16:25:51.223513Z|runtime|fd9b12f4-88a0-4ece-a217-94eb330e5c50]    Internal error
[MFLOG|0|2023-11-22T16:25:51.224221Z|runtime|8f1cd1c8-b9d1-42aa-9af2-67be19e0ff26]Traceback (most recent call last):
[MFLOG|0|2023-11-22T16:25:51.224280Z|runtime|f7827d32-47d8-4908-a1b5-2910b79d3ece]  File "/Users/fionasy/anaconda3/lib/python3.11/site-packages/metaflow/cli.py", line 1175, in main
[MFLOG|0|2023-11-22T16:25:51.224316Z|runtime|568edc06-5708-4094-9807-40cce56d3aa4]    start(auto_envvar_prefix="METAFLOW", obj=state)
[MFLOG|0|2023-11-22T16:25:51.224346Z|runtime|74f3dab1-755a-4928-b197-b98d8c033d90]  File "/Users/fionasy/anaconda3/lib/python3.11/site-packages/metaflow/tracing/__init__.py", line 27, in wrapper_func
[MFLOG|0|2023-11-22T16:25:51.224372Z|runtime|44b548b7-3238-473d-b5ea-056694efba79]    return func(args, kwargs)
[MFLOG|0|2023-11-22T16:25:51.248337Z|runtime|23b855d4-6f86-4beb-981c-2c375bdc5c3d]           ^^^^^^^^^^^^^^^^^^^^^
[MFLOG|0|2023-11-22T16:25:51.248464Z|runtime|1448775a-77f4-420c-a5b2-34b16982ae8c]  File "/Users/fionasy/anaconda3/lib/python3.11/site-packages/metaflow/_vendor/click/core.py", line 829, in __call__
[MFLOG|0|2023-11-22T16:25:51.248502Z|runtime|68e2e2c3-8968-4511-b093-4730f3962e32]    return self.main(args, kwargs)
[MFLOG|0|2023-11-22T16:25:51.248529Z|runtime|ace1ba4c-e3bc-46e4-988b-18d00d80dfae]           ^^^^^^^^^^^^^^^^^^^^^^^^^^
[MFLOG|0|2023-11-22T16:25:51.248556Z|runtime|8eb0a0a4-51c3-47a8-babf-c8f9fc87fb40]  File "/Users/fionasy/anaconda3/lib/python3.11/site-packages/metaflow/_vendor/click/core.py", line 782, in main
[MFLOG|0|2023-11-22T16:25:51.248578Z|runtime|36330287-1729-4f7f-96df-bcbd261e46ff]    rv = self.invoke(ctx)
[MFLOG|0|2023-11-22T16:25:51.248600Z|runtime|4fe63472-e23d-4ca5-bf08-f37996b031bb]         ^^^^^^^^^^^^^^^^
[MFLOG|0|2023-11-22T16:25:51.248624Z|runtime|2379a2e8-b33b-4228-ac75-0d1f12f95186]  File "/Users/fionasy/anaconda3/lib/python3.11/site-packages/metaflow/_vendor/click/core.py", line 1259, in invoke
[MFLOG|0|2023-11-22T16:25:51.248645Z|runtime|a17676fc-0f08-479c-8acc-8fa4f2608325]    return _process_result(sub_ctx.command.invoke(sub_ctx))
[MFLOG|0|2023-11-22T16:25:51.248667Z|runtime|8fa6a226-0c8f-400c-9d77-cbfe3011a60a]                           ^^^^^^^^^^^^^^^^^^^^^^^^^^^^^^^
[MFLOG|0|2023-11-22T16:25:51.248689Z|runtime|8ada9bc9-837c-4553-8833-c77011b91404]  File "/Users/fionasy/anaconda3/lib/python3.11/site-packages/metaflow/_vendor/click/core.py", line 1066, in invoke
[MFLOG|0|2023-11-22T16:25:51.248709Z|runtime|1cc788a1-0469-49c7-b902-bbaf56735ebf]    return ctx.invoke(self.callback, ctx.params)
[MFLOG|0|2023-11-22T16:25:51.248732Z|runtime|bfe54b9f-2500-407a-af6a-ce61cbecca95]           ^^^^^^^^^^^^^^^^^^^^^^^^^^^^^^^^^^^^^^^
[MFLOG|0|2023-11-22T16:25:51.248753Z|runtime|ab0f4d77-0a8a-4de0-9249-11e4e9081971]  File "/Users/fionasy/anaconda3/lib/python3.11/site-packages/metaflow/_vendor/click/core.py", line 610, in invoke
[MFLOG|0|2023-11-22T16:25:51.248771Z|runtime|16eb9176-67e1-444a-bf62-7d6ace03ae20]    return callback(args, kwargs)
[MFLOG|0|2023-11-22T16:25:51.248789Z|runtime|4724c0f7-9194-40e6-ba20-6eba6de7c360]           ^^^^^^^^^^^^^^^^^^^^^^^^^
[MFLOG|0|2023-11-22T16:25:51.248808Z|runtime|43250fa9-505e-4c57-b478-145498b30288]  File "/Users/fionasy/anaconda3/lib/python3.11/site-packages/metaflow/_vendor/click/decorators.py", line 21, in new_func
[MFLOG|0|2023-11-22T16:25:51.248828Z|runtime|7fecb7c0-497c-41f5-a1a5-d957d938da9a]    return f(get_current_context(), args, kwargs)
[MFLOG|0|2023-11-22T16:25:51.248845Z|runtime|f0d112ea-31ec-4c2d-aa5d-7c3e06325d41]           ^^^^^^^^^^^^^^^^^^^^^^^^^^^^^^^^^^^^^^^^^
[MFLOG|0|2023-11-22T16:25:51.248865Z|runtime|623fca43-38e8-47b0-a165-2c8900f4be89]  File "/Users/fionasy/anaconda3/lib/python3.11/site-packages/metaflow/cli.py", line 582, in step
[MFLOG|0|2023-11-22T16:25:51.248886Z|runtime|ef7312a7-cd5a-49ee-9c10-0759b9a4ae4e]    task.run_step(
[MFLOG|0|2023-11-22T16:25:51.248905Z|runtime|cbf2d6bf-66aa-408d-8328-04c3e6edb33a]  File "/Users/fionasy/anaconda3/lib/python3.11/site-packages/metaflow/task.py", line 596, in run_step
[MFLOG|0|2023-11-22T16:25:51.248924Z|runtime|fea133ce-9f95-45f6-b7f4-9cab46c77a94]    self._exec_step_function(step_func)
[MFLOG|0|2023-11-22T16:25:51.248942Z|runtime|828ede6f-63c9-4e45-b3c6-a603a3d8555d]  File "/Users/fionasy/anaconda3/lib/python3.11/site-packages/metaflow/task.py", line 57, in _exec_step_function
[MFLOG|0|2023-11-22T16:25:51.248956Z|runtime|ffc5b144-ef76-4da5-b5fc-36f692cd8136]    step_function()
[MFLOG|0|2023-11-22T16:25:51.248976Z|runtime|63376987-5845-41f5-8a52-a47487d1893a]  File "/Users/fionasy/Desktop/VSCODE/P2.py", line 9, in start
[MFLOG|0|2023-11-22T16:25:51.248995Z|runtime|fa6e646c-4f9e-465d-a4a7-465294b829a1]    self.process_training_file('big.txt')
[MFLOG|0|2023-11-22T16:25:51.249015Z|runtime|178a29cf-256d-4a2a-b4f8-0f779936f8e3]  File "/Users/fionasy/Desktop/VSCODE/P2.py", line 16, in process_training_file
[MFLOG|0|2023-11-22T16:25:51.249031Z|runtime|ac3707a8-38c7-4ec5-82b4-f7481bd3c232]    self.WORDS = Counter(words(open(file_path).read()))
[MFLOG|0|2023-11-22T16:25:51.249048Z|runtime|90f55316-04db-4d5b-90c5-68d151676361]                               ^^^^^^^^^^^^^^^
[MFLOG|0|2023-11-22T16:25:51.249064Z|runtime|af74fa0a-c884-424d-a5cd-10054c955bfe]FileNotFoundError: [Errno 2] No such file or directory: 'big.txt'
[MFLOG|0|2023-11-22T16:25:51.249084Z|runtime|b9362a0e-c141-41ac-bf7a-67bc577f71ee]
[MFLOG|0|2023-11-22T16:25:51.249403Z|runtime|a37fa81f-e54b-4d59-8308-d9b27d7203db]Task failed.