[MFLOG|0|2023-11-22T16:30:01.792014Z|runtime|36436356-5939-4a39-a7a3-0641a8c3b067]<flow P2 step start> failed:
[MFLOG|0|2023-11-22T16:30:01.793796Z|runtime|468a97b0-8dad-4f2d-949c-32e49076d734]    Internal error
[MFLOG|0|2023-11-22T16:30:01.794459Z|runtime|6f00c44f-64c3-4ed5-8421-d29a91dea3f9]Traceback (most recent call last):
[MFLOG|0|2023-11-22T16:30:01.794503Z|runtime|e5bf6e04-b451-4995-b50c-8a5809738b3e]  File "/Users/fionasy/anaconda3/lib/python3.11/site-packages/metaflow/cli.py", line 1175, in main
[MFLOG|0|2023-11-22T16:30:01.794542Z|runtime|6d59996d-e3c1-4747-b677-e808ccac66d2]    start(auto_envvar_prefix="METAFLOW", obj=state)
[MFLOG|0|2023-11-22T16:30:01.794572Z|runtime|75775663-2dc8-4ec5-ac89-9f6b519fb93f]  File "/Users/fionasy/anaconda3/lib/python3.11/site-packages/metaflow/tracing/__init__.py", line 27, in wrapper_func
[MFLOG|0|2023-11-22T16:30:01.794601Z|runtime|4bcb3b57-d17e-407d-a69f-6aefa3563e6b]    return func(args, kwargs)
[MFLOG|0|2023-11-22T16:30:01.817381Z|runtime|68207cf3-d551-4f3f-b370-787e7278f227]           ^^^^^^^^^^^^^^^^^^^^^
[MFLOG|0|2023-11-22T16:30:01.817502Z|runtime|2b053027-f846-4145-b8b4-b336f16ff3fe]  File "/Users/fionasy/anaconda3/lib/python3.11/site-packages/metaflow/_vendor/click/core.py", line 829, in __call__
[MFLOG|0|2023-11-22T16:30:01.817532Z|runtime|1673a424-df6a-429e-9e8b-0745c98348a3]    return self.main(args, kwargs)
[MFLOG|0|2023-11-22T16:30:01.817552Z|runtime|0c498cf0-7ce4-4c96-8f4f-c034268d2e50]           ^^^^^^^^^^^^^^^^^^^^^^^^^^
[MFLOG|0|2023-11-22T16:30:01.817569Z|runtime|769b8812-b611-4223-8eca-c476c5deef02]  File "/Users/fionasy/anaconda3/lib/python3.11/site-packages/metaflow/_vendor/click/core.py", line 782, in main
[MFLOG|0|2023-11-22T16:30:01.817587Z|runtime|742d64a9-6514-4e82-aa03-403545b5aca6]    rv = self.invoke(ctx)
[MFLOG|0|2023-11-22T16:30:01.817614Z|runtime|61800e20-7824-447f-bab5-311f4fb414f0]         ^^^^^^^^^^^^^^^^
[MFLOG|0|2023-11-22T16:30:01.817636Z|runtime|0c2e6c04-295e-4003-baf7-f4d45745edb1]  File "/Users/fionasy/anaconda3/lib/python3.11/site-packages/metaflow/_vendor/click/core.py", line 1259, in invoke
[MFLOG|0|2023-11-22T16:30:01.817661Z|runtime|932a6d1a-bf71-443a-97d1-8316abcd2d97]    return _process_result(sub_ctx.command.invoke(sub_ctx))
[MFLOG|0|2023-11-22T16:30:01.817685Z|runtime|521f4ada-30a4-48a3-81ba-c3621e13dd21]                           ^^^^^^^^^^^^^^^^^^^^^^^^^^^^^^^
[MFLOG|0|2023-11-22T16:30:01.817713Z|runtime|44b245f3-7f28-426b-b4ab-f024096c3240]  File "/Users/fionasy/anaconda3/lib/python3.11/site-packages/metaflow/_vendor/click/core.py", line 1066, in invoke
[MFLOG|0|2023-11-22T16:30:01.817734Z|runtime|870849a6-ca2a-4b5b-b025-39f43d1df139]    return ctx.invoke(self.callback, ctx.params)
[MFLOG|0|2023-11-22T16:30:01.817752Z|runtime|12b7b3d9-f8b6-4b0e-b441-61f524667514]           ^^^^^^^^^^^^^^^^^^^^^^^^^^^^^^^^^^^^^^^
[MFLOG|0|2023-11-22T16:30:01.817767Z|runtime|afb2aab1-fc2e-4fe1-9270-3ab3c16922d4]  File "/Users/fionasy/anaconda3/lib/python3.11/site-packages/metaflow/_vendor/click/core.py", line 610, in invoke
[MFLOG|0|2023-11-22T16:30:01.817787Z|runtime|ec59c286-619f-40f6-9ea2-42fb127c2662]    return callback(args, kwargs)
[MFLOG|0|2023-11-22T16:30:01.817807Z|runtime|ba648491-7fe3-4efc-a384-7ea2fc6d2ee3]           ^^^^^^^^^^^^^^^^^^^^^^^^^
[MFLOG|0|2023-11-22T16:30:01.817827Z|runtime|5bef9d09-9975-427a-a4ce-5db17e6db105]  File "/Users/fionasy/anaconda3/lib/python3.11/site-packages/metaflow/_vendor/click/decorators.py", line 21, in new_func
[MFLOG|0|2023-11-22T16:30:01.817841Z|runtime|c8d99f5b-daa3-4091-a050-348c179abafa]    return f(get_current_context(), args, kwargs)
[MFLOG|0|2023-11-22T16:30:01.817861Z|runtime|f0c0eeff-4700-4866-af99-d5724c6ceff9]           ^^^^^^^^^^^^^^^^^^^^^^^^^^^^^^^^^^^^^^^^^
[MFLOG|0|2023-11-22T16:30:01.817877Z|runtime|ad402572-b4f1-4f70-b779-ad4f5913914e]  File "/Users/fionasy/anaconda3/lib/python3.11/site-packages/metaflow/cli.py", line 582, in step
[MFLOG|0|2023-11-22T16:30:01.817898Z|runtime|2f11ec85-68ee-4f79-a0a1-bdbd876f2e7c]    task.run_step(
[MFLOG|0|2023-11-22T16:30:01.817919Z|runtime|ce085320-8606-40d8-95a7-9b8d392e6b16]  File "/Users/fionasy/anaconda3/lib/python3.11/site-packages/metaflow/task.py", line 596, in run_step
[MFLOG|0|2023-11-22T16:30:01.817936Z|runtime|c6b7c648-60f2-4a41-a103-52a9975aa891]    self._exec_step_function(step_func)
[MFLOG|0|2023-11-22T16:30:01.817958Z|runtime|0cf9da5a-f87b-40fb-8348-6f875b2c7de6]  File "/Users/fionasy/anaconda3/lib/python3.11/site-packages/metaflow/task.py", line 57, in _exec_step_function
[MFLOG|0|2023-11-22T16:30:01.817976Z|runtime|ddd97c7d-e9de-4d71-80ff-a7ac3cbe8f14]    step_function()
[MFLOG|0|2023-11-22T16:30:01.817992Z|runtime|cf1971ce-31fd-4e43-bc58-923856399a86]  File "/Users/fionasy/Desktop/VSCODE/P2.py", line 9, in start
[MFLOG|0|2023-11-22T16:30:01.818012Z|runtime|d2322362-f452-4de9-8f2d-e4b83a6a32ce]    self.process_training_file('big.txt')
[MFLOG|0|2023-11-22T16:30:01.818031Z|runtime|3d8668af-d469-46e6-86f4-f982964573ea]  File "/Users/fionasy/Desktop/VSCODE/P2.py", line 16, in process_training_file
[MFLOG|0|2023-11-22T16:30:01.818049Z|runtime|729c21b2-997d-405c-95a4-dbf1698b6926]    self.WORDS = Counter(words(open(file_path).read()))
[MFLOG|0|2023-11-22T16:30:01.818068Z|runtime|983a1940-87f2-4432-a581-fbc1b5b5bd50]                               ^^^^^^^^^^^^^^^
[MFLOG|0|2023-11-22T16:30:01.818087Z|runtime|1c93628c-347f-4757-bd48-b6d40e410804]FileNotFoundError: [Errno 2] No such file or directory: 'big.txt'
[MFLOG|0|2023-11-22T16:30:01.818108Z|runtime|c1e0b511-10a2-4c9a-843a-688fca278082]
[MFLOG|0|2023-11-22T16:30:01.818424Z|runtime|20b2d474-b507-45f0-9327-af6b314fb928]Task failed.